Workbook
Name Slicer_booking_channel1: #N/A
Name Slicer_booking_platform: #N/A
Name Slicer_booking_status: #N/A
Name Slicer_cancellation_reason: #N/A
Name Slicer_category: #N/A
Name Slicer_city: #N/A
Name Slicer_date: #N/A
Name Slicer_dim_hotels.property_name: #N/A
Name Slicer_MMM_yy: #N/A
Name Slicer_property_name: #N/A
Name Slicer_ratings_given1: #N/A
Name Slicer_revenue_generated1: #N/A
Name Slicer_room_category: #N/A
Name Slicer_room_category1: #N/A
Name Slicer_room_class: #N/A

Sheet Sheet1
B3: Row Labels | C3: Sum of revenue_realized | E3: Row Labels | F3: Sum of revenue_realized | H3: Row Labels | I3: Count of booking_status | K3: Row Labels | L3: Sum of revenue_realized | N3: Row Labels | O3: Count of booking_id
B4: Shodwe Bay | C4: 260051178 | E4: W 19 | F4: 140713020 | H4: Cancelled | I4: 33420 | K4: weekeday | L4: 1156923150 | N4: Corporate | O4: 34009
B5: Shodwe Blu | C5: 260855522 | E5: W 20 | F5: 128598765 | H5: Checked Out | I5: 94411 | K5: weekend | L5: 480234710 | N5: Direct | O5: 33127
B6: Shodwe City | C6: 285811939 | E6: W 21 | F6: 125266176 | H6: No Show | I6: 6759 | K6: (blank) | L6: 71613369 | N6: OTA | O6: 33772
B7: Shodwe Exotica | C7: 320312468 | E7: W 22 | F7: 129609069 | H7: Grand Total | I7: 134590 | K7: Grand Total | L7: 1708771229 | N7: Travel Agent | O7: 33682
B8: Shodwe Grands | C8: 211532764 | E8: W 23 | F8: 123789948 | N8: Grand Total | O8: 134590
B9: Shodwe Palace | C9: 304081863 | E9: W 24 | F9: 139583930
B10: Shodwe Seasons | C10: 66125495 | E10: W 25 | F10: 129558544
B11: Grand Total | C11: 1708771229 | E11: W 26 | F11: 124624861
E12: W 27 | F12: 137819495 | H12: Row Labels | I12: Sum of revenue_realized | K12: Row Labels | L12: Sum of revenue_realized
E13: W 28 | F13: 136300386 | H13: Jul 22 | I13: 499184195 | K13: Bangalore | L13: 420397050
B14: Row Labels | C14: Sum of revenue_realized | E14: W 29 | F14: 124964422 | H14: Jun 22 | I14: 564754400 | K14: Delhi | L14: 294500318
B15: Business | C15: 656019297 | E15: W 30 | F15: 108266696 | H15: May 22 | I15: 573219265 | K15: Hyderabad | L15: 325232870
B16: Luxury | C16: 1052751932 | E16: W 31 | F16: 84200266 | H16: (blank) | I16: 71613369 | K16: Mumbai | L16: 668640991
B17: Grand Total | C17: 1708771229 | E17: W 32 | F17: 3862282 | H17: Grand Total | I17: 1708771229 | K17: Grand Total | L17: 1708771229
E18: (blank) | F18: 71613369
E19: Grand Total | F19: 1708771229
B22: Row Labels | C22: Sum of revenue_realized | E22: Row Labels | F22: Count of booking_id | H22: Row Labels | I22: Count of booking_id | K22: Row Labels | L22: Count of cancellation_reason
B23: Elite | C23: 560271204 | E23: W 19 | F23: 11076 | H23: direct offline | I23: 6755 | K23: Change of plans | L23: 8214 | O23: Sum of revenue_realized | P23: Count of booking_id | Q23: Average of ratings_given | R23: Cancellation | S23: Occupancy
B24: Premium | C24: 462166344 | E24: W 20 | F24: 10166 | H24: direct online | I24: 13379 | K24: Found better deal | L24: 8359 | O24: 1708771229 | P24: 134590 | Q24: 3.6190039 | R24: =GETPIVOTDATA("[Measures].[Count of booking_status]",$H$3,"[Sheet1].[booking_status]","[Sheet1].[booking_status].&[Cancelled]")/GETPIVOTDATA("[Measures].[Count of booking_status]",$H$3) -> 0.24830968 | S24: 0.58
B25: Presidential | C25: 376752786 | E25: W 21 | F25: 9816 | H25: journey | I25: 8106 | K25: Not Cancelled | L25: 101170 | O25: =GETPIVOTDATA("[Measures].[Sum of revenue_realized 2]",$O$23)/10000000 -> 170.87712
B26: Standard | C26: 309580895 | E26: W 22 | F26: 10202 | H26: logtrip | I26: 14756 | K26: Personal reasons | L26: 8493
B27: Grand Total | C27: 1708771229 | E27: W 23 | F27: 9807 | H27: makeyourtrip | I27: 26898 | K27: Travel restrictions | L27: 8354
E28: W 24 | F28: 11015 | H28: others | I28: 55066 | K28: Grand Total | L28: 134590
E29: W 25 | F29: 10204 | H29: tripster | I29: 9630
B30: booking_status | C30: All | E30: W 26 | F30: 9795 | H30: Grand Total | I30: 134590 | O30: Total Revenues | P30: Cancellation % | Q30: Occupancy % | R30: Total Bookings | S30: Average Rating
E31: W 27 | F31: 10866 | O31: 1708771229 | P31: 0.24830968 | Q31: 0.57869256 | R31: 134590 | S31: 3.6190039
B32: Row Labels | C32: Count of booking_id | E32: W 28 | F32: 10721
B33: Shodwe Bay | C33: 21389 | E33: W 29 | F33: 9802 | H33: Row Labels | I33: Average of ratings_given | K33: Row Labels
B34: Shodwe Blu | C34: 21795 | E34: W 30 | F34: 8542 | H34: Shodwe Bay | I34: 3.7089286 | K34: Bangalore
B35: Shodwe City | C35: 23323 | E35: W 31 | F35: 6572 | H35: Shodwe Blu | I35: 3.9596501 | K35: Delhi
B36: Shodwe Exotica | C36: 23441 | E36: W 32 | F36: 290 | H36: Shodwe City | I36: 3.6947993 | K36: Hyderabad
B37: Shodwe Grands | C37: 17035 | E37: (blank) | F37: 5716 | H37: Shodwe Exotica | I37: 3.6192409 | K37: Mumbai
B38: Shodwe Palace | C38: 23625 | E38: Grand Total | F38: 134590 | H38: Shodwe Grands | I38: 3.0998755 | K38: Grand Total
B39: Shodwe Seasons | C39: 3982 | H39: Shodwe Palace | I39: 3.7495446
B40: Grand Total | C40: 134590 | H40: Shodwe Seasons | I40: 2.2948565 | K40: Total Revenue
B41: booking_status | C41: All | H41: Grand Total | I41: 3.6190039 | K41: =SUM([1]!Sheet1__2[revenue_realized]) -> #REF!
B43: Row Labels | C43: Count of booking_id | E43: Row Labels | F43: Count of booking_id
B44: Elite | C44: 49505 | E44: Elite | F44: 49505 | H44: Row Labels | I44: Average of ratings_given
B45: Premium | C45: 30566 | E45: Premium | F45: 30566 | H45: Elite | I45: 3.6029023
...

Sheet HOME

Sheet Sheet3

Sheet Overall Analysis
B5: Total Revenue | D5: Total Bookings | G5: Average Rate
B6: ='Total Revenue'!B4 -> 1708771229 | D6: =AB19 -> 134590 | G6: ='Average Rating'!B4 -> 3.6190039
C8: Cancellation % | F8: Occupancy %
C9: ='Cancellation %'!C4 -> 0.24830968 | F9: ='Occupancy %'!D4 -> 0.57869256
AB14: ='Total Revenue'!B4 -> 1708771229
AB19: ='Total Bookings'!B4 -> 134590
AC21: =#REF! -> #REF!
AC23: ='Cancellation %'!B4 -> 134590
AB24: ='Occupancy %'!B4 -> 232576

Sheet Revenue analysis
A6: Total Revenue
A7: =Y19 -> 1708771229
A9: Aerage Rate
A10: ='Average Rating'!B4 -> 3.6190039 | Y10: ='Total Bookings'!B4 -> 134590
A13: Total Bookings
A14: =Y10 -> 134590
Y15: ='Total Bookings'!B4 -> 134590
A17: Cancellation % | AA17: ='Cancellation %'!B4 -> 134590
A18: ='Cancellation %'!$C$4 -> 0.24830968
Y19: ='Total Revenue'!B4 -> 1708771229
AA20: ='Occupancy %'!B4 -> 232576
A21: Occupancy %
A22: ='Occupancy %'!D4 -> 0.57869256 | Y22: =#REF! -> #REF!
Z24: ='Total Bookings'!B4 -> 134590
B29: Total Bookings
B30: =Z24 -> 134590

Sheet Cancellation analysis
B8: Total Revenues
B9: =Y19 -> 1708771229
B12: Total Bookings
B13: =Y23 -> 134590 | Y13: =#REF! -> #REF!
B16: Average Rating
B17: ='Average Rating'!B4 -> 3.6190039
Y19: ='Total Revenue'!B4 -> 1708771229 | AA19: ='Cancellation %'!B4 -> 134590
B21: Cancellation %
B22: ='Cancellation %'!C4 -> 0.24830968
Y23: ='Total Bookings'!B4 -> 134590
B26: Occupancy %
B27: ='Occupancy %'!D4 -> 0.57869256 | AA27: ='Occupancy %'!B4 -> 232576

Sheet Booking Trends 
C6: Total Booking
C7: =Y18 -> 134590
Y18: ='Total Bookings'!B4 -> 134590

Sheet Total Revenue
B3: Total Revenues
B4: 1708771229

Sheet Cancellation %
B3: Total Bookings | C3: Cancellation % | D3: Total cancelled Bookings
B4: 134590 | C4: 0.24830968 | D4: 33420

Sheet Occupancy %
B3: Total Capacity | C3: Total Successful Bookings | D3: Occupancy %
B4: 232576 | C4: 134590 | D4: 0.57869256

Sheet Total Bookings
B3: Total Bookings
B4: 134590

Sheet Average Rating
B3: Average Rating
B4: 3.6190039

Sheet WEEK NUM
B3: Count of week no | C3: Total Revenues
B4: 92 | C4: 1708771229

Sheet WEEK DAY WEEKEND
B3: Row Labels | C3: Total Revenues
B4: weekeday | C4: 1156923150
B5: weekend | C5: 480234710
B6: (blank) | C6: 71613369
B7: Grand Total | C7: 1708771229

Sheet Sheet2

Sheet Sheet5

Sheet Sheet6

Sheet Sheet8
